Workbook

Sheet Dados COTA-ÁREA-VOLUME
G2: HIDROLOGIA
G3: BALANÇO DE RESERVATÓRIO
B4: PROGRAMA DE MONITORIA DO DECA 2022.2 - MONITOR EMANUEL GOMES SOARES
A6: Cota (m) | B6: Área (m2) | C6: Volume (m3)
A7: 340.36 | B7: 0 | C7: 0
A8: 342.36 | B8: 200 | C8: 4000
A9: 343 | B9: 37223 | C9: 16994
A10: 344 | B10: 70593 | C10: 70593
A11: 345 | B11: 142867 | C11: 174286
A12: 346 | B12: 257180 | C12: 366771
A13: 347 | B13: 421869 | C13: 707956
A14: 348 | B14: 631536 | C14: 1230617
A15: 349 | B15: 873903 | C15: 1981542
A16: 350 | B16: 1158564 | C16: 2990176
A17: 351 | B17: 1506467 | C17: 4314820
A18: 352 | B18: 1866251 | C18: 5996469
... A49: 380 | B49: 45587858 | C49: 501383005

Sheet Dados de demanda e evaporação
G2: HIDROLOGIA
G3: BALANÇO DE RESERVATÓRIO
B4: PROGRAMA DE MONITORIA DO DECA 2022.2 - MONITOR EMANUEL GOMES SOARES
A6: Mês | B6: Qdem (m3/s) | C6: Evp (mm) | D6: Evp (m)
A7: Janeiro | B7: 0.6 | C7: 161.2 | D7: =Tabela2[[#This Row],[Evp (mm)]]/1000 -> 0.1612
A8: Fevereiro | B8: 0.6 | C8: 142.8 | D8: =Tabela2[[#This Row],[Evp (mm)]]/1000 -> 0.1428
A9: Março | B9: 0.6 | C9: 139.5 | D9: =Tabela2[[#This Row],[Evp (mm)]]/1000 -> 0.1395
A10: Abril | B10: 0.6 | C10: 114 | D10: =Tabela2[[#This Row],[Evp (mm)]]/1000 -> 0.114
A11: Maio | B11: 0.6 | C11: 89.9 | D11: =Tabela2[[#This Row],[Evp (mm)]]/1000 -> 0.0899
A12: Junho | B12: 0.6 | C12: 75 | D12: =Tabela2[[#This Row],[Evp (mm)]]/1000 -> 0.075
A13: Julho | B13: 0.6 | C13: 80.6 | D13: =Tabela2[[#This Row],[Evp (mm)]]/1000 -> 0.0806
A14: Agosto | B14: 0.6 | C14: 99.2 | D14: =Tabela2[[#This Row],[Evp (mm)]]/1000 -> 0.0992
A15: Setembro | B15: 0.6 | C15: 126 | D15: =Tabela2[[#This Row],[Evp (mm)]]/1000 -> 0.126
A16: Outubro | B16: 0.6 | C16: 151.9 | D16: =Tabela2[[#This Row],[Evp (mm)]]/1000 -> 0.1519
A17: Novembro | B17: 0.6 | C17: 156 | D17: =Tabela2[[#This Row],[Evp (mm)]]/1000 -> 0.156
A18: Dezembro | B18: 0.6 | C18: 161.2 | D18: =Tabela2[[#This Row],[Evp (mm)]]/1000 -> 0.1612

Sheet Vazões afluentes
A3: c) Vazões afluentes
A6: Mês | B6: Vazão Afluente (m3/s)
A7: 31778 | B7: 7.4
A8: 31809 | B8: 18.2
A9: 31837 | B9: 33.6
A10: 31868 | B10: 18.5
A11: 31898 | B11: 9.5
A12: 31929 | B12: 26.9
A13: 31959 | B13: 19
A14: 31990 | B14: 13.7
A15: 32021 | B15: 10.1
A16: 32051 | B16: 6.6
A17: 32082 | B17: 4.5
A18: 32112 | B18: 4.7
... A42: 32843 | B42: 10.1

Sheet Dados de precipitação
A3: c) Precipitação
A6: Mês | B6: Precipitação (em mm)
A7: 44562 | B7: 74.5
A8: 44593 | B8: 104.6
A9: 44621 | B9: 227.2
A10: 44652 | B10: 246
A11: 44682 | B11: 61.6
A12: 44713 | B12: 257.6
A13: 44743 | B13: 170.2
A14: 44774 | B14: 100.2
A15: 44805 | B15: 35.3
A16: 44835 | B16: 37.9
A17: 44866 | B17: 5.4
A18: 44896 | B18: 8.3
... A42: 45627 | B42: 76.7

Sheet Dimensionamento (2017)
G2: HIDROLOGIA
G3: BALANÇO DE RESERVATÓRIO
B4: PROGRAMA DE MONITORIA DO DECA 2022.2 - MONITOR EMANUEL GOMES SOARES
A5: com equação linear
A8: Volume inicial (m3) | D8: =15312665.88 -> 15312666 | F8: AESA 28/02/2017
A9: Capacidade total de armazenamento | D9: 411686287 | E9: AESA
A10: volume de porão | D10: =1%*$D$9 -> 4116862.9
A11: Capacidade útil de armazenamento | D11: =D9-D10 -> 4.0756942e+08
E14: EVAPOTRANSPIRAÇÃO | H14: DEMANDA
A15: Mês | B15: Número de dias do mês | C15: Volume (em m3) | D15: Área (m2) | E15: Evaporação | F15: Volume referente a E (m3) | G15: Afluxo Líquido (m3) | H15: Demandas (m3/s) | I15: Volumes das demandas (m3) | J15: Volumes acumulados | K15: Volume final do mês
A16: 42795 | B16: 31 | C16: =$D$8 -> 15312666 | D16: =0.2297*(C16)+226886 -> 3744205.4 | E16: ='Dados de demanda e evaporação'!$D$9 -> 0.1395 | F16: =E16*D16 -> 522316.65 | G16: =(C16-F16) -> 14790349 | H16: ='Dados de demanda e evaporação'!$B$7 -> 0.6 | I16: =H16*B16*(3600*24) -> 1607040 | J16: =G16-I16 -> 13183309 | K16: =IF(J16<$D$9,J16,$D$9) -> 13183309
A17: 42826 | B17: 30 | C17: =K16 -> 13183309 | D17: =22.256*C17^0.7153 -> 2756770.4 | E17: ='Dados de demanda e evaporação'!$D$10 -> 0.114 | F17: =E17*D17 -> 314271.82 | G17: =(C17-F17) -> 12869037 | H17: ='Dados de demanda e evaporação'!$B$7 -> 0.6 | I17: =H17*B17*(3600*24) -> 1555200 | J17: =G17-I17 -> 11313837 | K17: =IF(J17<$D$9,J17,$D$9) -> 11313837
A18: 42856 | B18: 31 | C18: =K17 -> 11313837 | D18: =22.256*C18^0.7153 -> 2471122.6 | E18: ='Dados de demanda e evaporação'!$D$11 -> 0.0899 | F18: =E18*D18 -> 222153.92 | G18: =(C18-F18) -> 11091683 | H18: ='Dados de demanda e evaporação'!$B$7 -> 0.6 | I18: =H18*B18*(3600*24) -> 1607040 | J18: =G18-I18 -> 9484643.5 | K18: =IF(J18<$D$9,J18,$D$9) -> 9484643.5 | M18: VOLUME MÍNIMO | O18: =MIN(K16:K23) -> 798583.24
A19: 42887 | B19: 30 | C19: =K18 -> 9484643.5 | D19: =22.256*C19^0.7153 -> 2178262.6 | E19: ='Dados de demanda e evaporação'!$D$12 -> 0.075 | F19: =E19*D19 -> 163369.7 | G19: =(C19-F19) -> 9321273.8 | H19: ='Dados de demanda e evaporação'!$B$7 -> 0.6 | I19: =H19*B19*(3600*24) -> 1555200 | J19: =G19-I19 -> 7766073.8 | K19: =IF(J19<$D$9,J19,$D$9) -> 7766073.8
A20: 42917 | B20: 31 | C20: =K19 -> 7766073.8 | D20: =22.256*C20^0.7153 -> 1888027.2 | E20: ='Dados de demanda e evaporação'!$D$13 -> 0.0806 | F20: =E20*D20 -> 152175 | G20: =(C20-F20) -> 7613898.8 | H20: ='Dados de demanda e evaporação'!$B$7 -> 0.6 | I20: =H20*B20*(3600*24) -> 1607040 | J20: =G20-I20 -> 6006858.8 | K20: =IF(J20<$D$9,J20,$D$9) -> 6006858.8
A21: 42948 | B21: 31 | C21: =K20 -> 6006858.8 | D21: =22.256*C21^0.7153 -> 1571135.4 | E21: ='Dados de demanda e evaporação'!$D$14 -> 0.0992 | F21: =E21*D21 -> 155856.63 | G21: =(C21-F21) -> 5851002.2 | H21: ='Dados de demanda e evaporação'!$B$7 -> 0.6 | I21: =H21*B21*(3600*24) -> 1607040 | J21: =G21-I21 -> 4243962.2 | K21: =IF(J21<$D$9,J21,$D$9) -> 4243962.2
A22: 42979 | B22: 30 | C22: =K21 -> 4243962.2 | D22: =22.256*C22^0.7153 -> 1225440 | E22: ='Dados de demanda e evaporação'!$D$15 -> 0.126 | F22: =E22*D22 -> 154405.45 | G22: =(C22-F22) -> 4089556.7 | H22: ='Dados de demanda e evaporação'!$B$7 -> 0.6 | I22: =H22*B22*(3600*24) -> 1555200 | J22: =G22-I22 -> 2534356.7 | K22: =IF(J22<$D$9,J22,$D$9) -> 2534356.7
A23: 43009 | B23: 31 | C23: =K22 -> 2534356.7 | D23: =22.256*C23^0.7153 -> 847488.3 | E23: ='Dados de demanda e evaporação'!$D$16 -> 0.1519 | F23: =E23*D23 -> 128733.47 | G23: =(C23-F23) -> 2405623.2 | H23: ='Dados de demanda e evaporação'!$B$7 -> 0.6 | I23: =H23*B23*(3600*24) -> 1607040 | J23: =G23-I23 -> 798583.24 | K23: =IF(J23<$D$9,J23,$D$9) -> 798583.24
A24: 43040 | B24: 30 | C24: =K23 -> 798583.24 | D24: =22.256*C24^0.7153 -> 371002.42 | E24: ='Dados de demanda e evaporação'!$D$17 -> 0.156 | F24: =E24*D24 -> 57876.378 | G24: =(C24-F24) -> 740706.86 | H24: ='Dados de demanda e evaporação'!$B$7 -> 0.6 | I24: =H24*B24*(3600*24) -> 1555200 | J24: =G24-I24 -> -814493.14 | K24: =IF(J24<$D$9,J24,$D$9) -> -814493.14 | L24: volume zerou pois deu negativo!
A25: 43070 | B25: 31 | C25: =K24 -> -814493.14 | D25: =22.256*C25^0.7153 -> #NUM! | E25: ='Dados de demanda e evaporação'!$D$18 -> 0.1612 | F25: =E25*D25 -> #NUM! | G25: =(C25-F25) -> #NUM! | H25: ='Dados de demanda e evaporação'!$B$7 -> 0.6 | I25: =H25*B25*(3600*24) -> 1607040 | J25: =G25-I25 -> #NUM! | K25: =IF(J25<$D$9,J25,$D$9) -> #NUM!
A26: 43101 | B26: 31 | C26: =K25 -> #NUM! | D26: =22.256*C26^0.7153 -> #NUM! | E26: ='Dados de demanda e evaporação'!$D$7 -> 0.1612 | F26: =E26*D26 -> #NUM! | G26: =(C26-F26) -> #NUM! | H26: ='Dados de demanda e evaporação'!$B$7 -> 0.6 | I26: =H26*B26*(3600*24) -> 1607040 | J26: =G26-I26 -> #NUM! | K26: =IF(J26<$D$9,J26,$D$9) -> #NUM!
A27: 43132 | B27: 28 | C27: =K26 -> #NUM! | D27: =22.256*C27^0.7153 -> #NUM! | E27: ='Dados de demanda e evaporação'!$D$8 -> 0.1428 | F27: =E27*D27 -> #NUM! | G27: =(C27-F27) -> #NUM! | H27: ='Dados de demanda e evaporação'!$B$7 -> 0.6 | I27: =H27*B27*(3600*24) -> 1451520 | J27: =G27-I27 -> #NUM! | K27: =IF(J27<$D$9,J27,$D$9) -> #NUM!
A28: 43160 | B28: 31 | C28: =K27 -> #NUM! | D28: =22.256*C28^0.7153 -> #NUM! | E28: ='Dados de demanda e evaporação'!$D$9 -> 0.1395 | F28: =E28*D28 -> #NUM! | G28: =(C28-F28) -> #NUM! | H28: ='Dados de demanda e evaporação'!$B$7 -> 0.6 | I28: =H28*B28*(3600*24) -> 1607040 | J28: =G28-I28 -> #NUM! | K28: =IF(J28<$D$9,J28,$D$9) -> #NUM!
A29: 43191 | B29: 30 | C29: =K28 -> #NUM! | D29: =22.256*C29^0.7153 -> #NUM! | E29: ='Dados de demanda e evaporação'!$D$10 -> 0.114 | F29: =E29*D29 -> #NUM! | G29: =(C29-F29) -> #NUM! | H29: ='Dados de demanda e evaporação'!$B$7 -> 0.6 | I29: =H29*B29*(3600*24) -> 1555200 | J29: =G29-I29 -> #NUM! | K29: =IF(J29<$D$9,J29,$D$9) -> #NUM!
A30: 43221 | B30: 31 | C30: =K29 -> #NUM! | D30: =22.256*C30^0.7153 -> #NUM! | E30: ='Dados de demanda e evaporação'!$D$11 -> 0.0899 | F30: =E30*D30 -> #NUM! | G30: =(C30-F30) -> #NUM! | H30: ='Dados de demanda e evaporação'!$B$7 -> 0.6 | I30: =H30*B30*(3600*24) -> 1607040 | J30: =G30-I30 -> #NUM! | K30: =IF(J30<$D$9,J30,$D$9) -> #NUM!
A31: 43252 | B31: 30 | C31: =K30 -> #NUM! | D31: =22.256*C31^0.7153 -> #NUM! | E31: ='Dados de demanda e evaporação'!$D$12 -> 0.075 | F31: =E31*D31 -> #NUM! | G31: =(C31-F31) -> #NUM! | H31: ='Dados de demanda e evaporação'!$B$7 -> 0.6 | I31: =H31*B31*(3600*24) -> 1555200 | J31: =G31-I31 -> #NUM! | K31: =IF(J31<$D$9,J31,$D$9) -> #NUM!
A32: 43282 | B32: 31 | C32: =K31 -> #NUM! | D32: =22.256*C32^0.7153 -> #NUM! | E32: ='Dados de demanda e evaporação'!$D$13 -> 0.0806 | F32: =E32*D32 -> #NUM! | G32: =(C32-F32) -> #NUM! | H32: ='Dados de demanda e evaporação'!$B$7 -> 0.6 | I32: =H32*B32*(3600*24) -> 1607040 | J32: =G32-I32 -> #NUM! | K32: =IF(J32<$D$9,J32,$D$9) -> #NUM!
A33: 43313 | B33: 31 | C33: =K32 -> #NUM! | D33: =22.256*C33^0.7153 -> #NUM! | E33: ='Dados de demanda e evaporação'!$D$14 -> 0.0992 | F33: =E33*D33 -> #NUM! | G33: =(C33-F33) -> #NUM! | H33: ='Dados de demanda e evaporação'!$B$7 -> 0.6 | I33: =H33*B33*(3600*24) -> 1607040 | J33: =G33-I33 -> #NUM! | K33: =IF(J33<$D$9,J33,$D$9) -> #NUM!
A34: 43344 | B34: 30 | C34: =K33 -> #NUM! | D34: =22.256*C34^0.7153 -> #NUM! | E34: ='Dados de demanda e evaporação'!$D$15 -> 0.126 | F34: =E34*D34 -> #NUM! | G34: =(C34-F34) -> #NUM! | H34: ='Dados de demanda e evaporação'!$B$7 -> 0.6 | I34: =H34*B34*(3600*24) -> 1555200 | J34: =G34-I34 -> #NUM! | K34: =IF(J34<$D$9,J34,$D$9) -> #NUM!
A35: 43374 | B35: 31 | C35: =K34 -> #NUM! | D35: =22.256*C35^0.7153 -> #NUM! | E35: ='Dados de demanda e evaporação'!$D$16 -> 0.1519 | F35: =E35*D35 -> #NUM! | G35: =(C35-F35) -> #NUM! | H35: ='Dados de demanda e evaporação'!$B$7 -> 0.6 | I35: =H35*B35*(3600*24) -> 1607040 | J35: =G35-I35 -> #NUM! | K35: =IF(J35<$D$9,J35,$D$9) -> #NUM!
A36: 43405 | B36: 30 | C36: =K35 -> #NUM! | D36: =22.256*C36^0.7153 -> #NUM! | E36: ='Dados de demanda e evaporação'!$D$17 -> 0.156 | F36: =E36*D36 -> #NUM! | G36: =(C36-F36) -> #NUM! | H36: ='Dados de demanda e evaporação'!$B$7 -> 0.6 | I36: =H36*B36*(3600*24) -> 1555200 | J36: =G36-I36 -> #NUM! | K36: =IF(J36<$D$9,J36,$D$9) -> #NUM!
A37: 43435 | B37: 31 | C37: =K36 -> #NUM! | D37: =22.256*C37^0.7153 -> #NUM! | E37: ='Dados de demanda e evaporação'!$D$18 -> 0.1612 | F37: =E37*D37 -> #NUM! | G37: =(C37-F37) -> #NUM! | H37: ='Dados de demanda e evaporação'!$B$7 -> 0.6 | I37: =H37*B37*(3600*24) -> 1607040 | J37: =G37-I37 -> #NUM! | K37: =IF(J37<$D$9,J37,$D$9) -> #NUM!
A38: 43466 | B38: 31 | C38: =K37 -> #NUM! | D38: =22.256*C38^0.7153 -> #NUM! | E38: ='Dados de demanda e evaporação'!$D$7 -> 0.1612 | F38: =E38*D38 -> #NUM! | G38: =(C38-F38) -> #NUM! | H38: ='Dados de demanda e evaporação'!$B$7 -> 0.6 | I38: =H38*B38*(3600*24) -> 1607040 | J38: =G38-I38 -> #NUM! | K38: =IF(J38<$D$9,J38,$D$9) -> #NUM!
A39: 43497 | B39: 28 | C39: =K38 -> #NUM! | D39: =22.256*C39^0.7153 -> #NUM! | E39: ='Dados de demanda e evaporação'!$D$8 -> 0.1428 | F39: =E39*D39 -> #NUM! | G39: =(C39-F39) -> #NUM! | H39: ='Dados de demanda e evaporação'!$B$7 -> 0.6 | I39: =H39*B39*(3600*24) -> 1451520 | J39: =G39-I39 -> #NUM! | K39: =IF(J39<$D$9,J39,$D$9) -> #NUM!
A40: 43525 | B40: 31 | C40: =K39 -> #NUM! | D40: =22.256*C40^0.7153 -> #NUM! | E40: ='Dados de demanda e evaporação'!$D$9 -> 0.1395 | F40: =E40*D40 -> #NUM! | G40: =(C40-F40) -> #NUM! | H40: ='Dados de demanda e evaporação'!$B$7 -> 0.6 | I40: =H40*B40*(3600*24) -> 1607040 | J40: =G40-I40 -> #NUM! | K40: =IF(J40<$D$9,J40,$D$9) -> #NUM!
A41: 43556 | B41: 30 | C41: =K40 -> #NUM! | D41: =22.256*C41^0.7153 -> #NUM! | E41: ='Dados de demanda e evaporação'!$D$10 -> 0.114 | F41: =E41*D41 -> #NUM! | G41: =(C41-F41) -> #NUM! | H41: ='Dados de demanda e evaporação'!$B$7 -> 0.6 | I41: =H41*B41*(3600*24) -> 1555200 | J41: =G41-I41 -> #NUM! | K41: =IF(J41<$D$9,J41,$D$9) -> #NUM!
A42: 43586 | B42: 31 | C42: =K41 -> #NUM! | D42: =22.256*C42^0.7153 -> #NUM! | E42: ='Dados de demanda e evaporação'!$D$11 -> 0.0899 | F42: =E42*D42 -> #NUM! | G42: =(C42-F42) -> #NUM! | H42: ='Dados de demanda e evaporação'!$B$7 -> 0.6 | I42: =H42*B42*(3600*24) -> 1607040 | J42: =G42-I42 -> #NUM! | K42: =IF(J42<$D$9,J42,$D$9) -> #NUM!
A43: 43617 | B43: 30 | C43: =K42 -> #NUM! | D43: =22.256*C43^0.7153 -> #NUM! | E43: ='Dados de demanda e evaporação'!$D$12 -> 0.075 | F43: =E43*D43 -> #NUM! | G43: =(C43-F43) -> #NUM! | H43: ='Dados de demanda e evaporação'!$B$7 -> 0.6 | I43: =H43*B43*(3600*24) -> 1555200 | J43: =G43-I43 -> #NUM! | K43: =IF(J43<$D$9,J43,$D$9) -> #NUM!
A44: 43647 | B44: 31 | C44: =K43 -> #NUM! | D44: =22.256*C44^0.7153 -> #NUM! | E44: ='Dados de demanda e evaporação'!$D$13 -> 0.0806 | F44: =E44*D44 -> #NUM! | G44: =(C44-F44) -> #NUM! | H44: ='Dados de demanda e evaporação'!$B$7 -> 0.6 | I44: =H44*B44*(3600*24) -> 1607040 | J44: =G44-I44 -> #NUM! | K44: =IF(J44<$D$9,J44,$D$9) -> #NUM!
A45: 43678 | B45: 31 | C45: =K44 -> #NUM! | D45: =22.256*C45^0.7153 -> #NUM! | E45: ='Dados de demanda e evaporação'!$D$14 -> 0.0992 | F45: =E45*D45 -> #NUM! | G45: =(C45-F45) -> #NUM! | H45: ='Dados de demanda e evaporação'!$B$7 -> 0.6 | I45: =H45*B45*(3600*24) -> 1607040 | J45: =G45-I45 -> #NUM! | K45: =IF(J45<$D$9,J45,$D$9) -> #NUM!
...

Sheet Dimensionamento 2016
G2: HIDROLOGIA
G3: BALANÇO DE RESERVATÓRIO
B4: PROGRAMA DE MONITORIA DO DECA 2022.2 - MONITOR EMANUEL GOMES SOARES
A6: com equação linear
A9: Volume inicial (m3) | D9: =49086672.63 -> 49086673 | F9: AESA 31/01/2016
A10: Capacidade total de armazenamento | D10: 411686287 | E10: AESA
A11: volume de porão | D11: =1%*$D$10 -> 4116862.9
A12: Capacidade útil de armazenamento | D12: =D10-D11 -> 4.0756942e+08
A16: Mês | B16: Número de dias do mês | C16: Volume (em m3) | D16: Área (m2) | E16: Evaporação | F16: Volume referente a E (m3) | G16: Afluxo Líquido (m3) | H16: Demandas (m3/s) | I16: Volumes das demandas (m3) | J16: Volumes acumulados | K16: Volume final do mês
A17: 42401 | B17: 28 | C17: =$D$9 -> 49086673 | D17: =0.2297*(C17)+226886 -> 11502095 | E17: ='Dados de demanda e evaporação'!$D8 -> 0.1428 | F17: =E17*D17 -> 1642499.1 | G17: =(C17-F17) -> 47444174 | H17: ='Dados de demanda e evaporação'!$B$7 -> 0.6 | I17: =H17*B17*(3600*24) -> 1451520 | J17: =G17-I17 -> 45992654 | K17: =IF(J17<$D$10,J17,$D$10) -> 45992654
A18: 42826 | B18: 31 | C18: =K17 -> 45992654 | D18: =22.256*C18^0.7153 -> 6738576.7 | E18: ='Dados de demanda e evaporação'!$D9 -> 0.1395 | F18: =E18*D18 -> 940031.44 | G18: =(C18-F18) -> 45052622 | H18: ='Dados de demanda e evaporação'!$B$7 -> 0.6 | I18: =H18*B18*(3600*24) -> 1607040 | J18: =G18-I18 -> 43445582 | K18: =IF(J18<$D$10,J18,$D$10) -> 43445582
A19: 42856 | B19: 30 | C19: =K18 -> 43445582 | D19: =22.256*C19^0.7153 -> 6469483.6 | E19: ='Dados de demanda e evaporação'!$D10 -> 0.114 | F19: =E19*D19 -> 737521.13 | G19: =(C19-F19) -> 42708061 | H19: ='Dados de demanda e evaporação'!$B$7 -> 0.6 | I19: =H19*B19*(3600*24) -> 1555200 | J19: =G19-I19 -> 41152861 | K19: =IF(J19<$D$10,J19,$D$10) -> 41152861 | M19: VOLUME MÍNIMO | O19: =MIN(K17:K24) -> 30533270
A20: 42887 | B20: 31 | C20: =K19 -> 41152861 | D20: =22.256*C20^0.7153 -> 6223396.3 | E20: ='Dados de demanda e evaporação'!$D11 -> 0.0899 | F20: =E20*D20 -> 559483.33 | G20: =(C20-F20) -> 40593378 | H20: ='Dados de demanda e evaporação'!$B$7 -> 0.6 | I20: =H20*B20*(3600*24) -> 1607040 | J20: =G20-I20 -> 38986338 | K20: =IF(J20<$D$10,J20,$D$10) -> 38986338
A21: 42917 | B21: 30 | C21: =K20 -> 38986338 | D21: =22.256*C21^0.7153 -> 5987241.6 | E21: ='Dados de demanda e evaporação'!$D12 -> 0.075 | F21: =E21*D21 -> 449043.12 | G21: =(C21-F21) -> 38537294 | H21: ='Dados de demanda e evaporação'!$B$7 -> 0.6 | I21: =H21*B21*(3600*24) -> 1555200 | J21: =G21-I21 -> 36982094 | K21: =IF(J21<$D$10,J21,$D$10) -> 36982094
A22: 42948 | B22: 31 | C22: =K21 -> 36982094 | D22: =22.256*C22^0.7153 -> 5765426.4 | E22: ='Dados de demanda e evaporação'!$D13 -> 0.0806 | F22: =E22*D22 -> 464693.37 | G22: =(C22-F22) -> 36517401 | H22: ='Dados de demanda e evaporação'!$B$7 -> 0.6 | I22: =H22*B22*(3600*24) -> 1607040 | J22: =G22-I22 -> 34910361 | K22: =IF(J22<$D$10,J22,$D$10) -> 34910361
A23: 42979 | B23: 31 | C23: =K22 -> 34910361 | D23: =22.256*C23^0.7153 -> 5532511.9 | E23: ='Dados de demanda e evaporação'!$D14 -> 0.0992 | F23: =E23*D23 -> 548825.18 | G23: =(C23-F23) -> 34361536 | H23: ='Dados de demanda e evaporação'!$B$7 -> 0.6 | I23: =H23*B23*(3600*24) -> 1607040 | J23: =G23-I23 -> 32754496 | K23: =IF(J23<$D$10,J23,$D$10) -> 32754496
A24: 43009 | B24: 30 | C24: =K23 -> 32754496 | D24: =22.256*C24^0.7153 -> 5285917.8 | E24: ='Dados de demanda e evaporação'!$D15 -> 0.126 | F24: =E24*D24 -> 666025.64 | G24: =(C24-F24) -> 32088470 | H24: ='Dados de demanda e evaporação'!$B$7 -> 0.6 | I24: =H24*B24*(3600*24) -> 1555200 | J24: =G24-I24 -> 30533270 | K24: =IF(J24<$D$10,J24,$D$10) -> 30533270
A25: 43040 | B25: 31 | C25: =K24 -> 30533270 | D25: =22.256*C25^0.7153 -> 5026960.5 | E25: ='Dados de demanda e evaporação'!$D16 -> 0.1519 | F25: =E25*D25 -> 763595.3 | G25: =(C25-F25) -> 29769675 | H25: ='Dados de demanda e evaporação'!$B$7 -> 0.6 | I25: =H25*B25*(3600*24) -> 1607040 | J25: =G25-I25 -> 28162635 | K25: =IF(J25<$D$10,J25,$D$10) -> 28162635
A26: 43070 | B26: 30 | C26: =K25 -> 28162635 | D26: =22.256*C26^0.7153 -> 4744587 | E26: ='Dados de demanda e evaporação'!$D17 -> 0.156 | F26: =E26*D26 -> 740155.57 | G26: =(C26-F26) -> 27422479 | H26: ='Dados de demanda e evaporação'!$B$7 -> 0.6 | I26: =H26*B26*(3600*24) -> 1555200 | J26: =G26-I26 -> 25867279 | K26: =IF(J26<$D$10,J26,$D$10) -> 25867279
A27: 43101 | B27: 31 | C27: =K26 -> 25867279 | D27: =22.256*C27^0.7153 -> 4464653.2 | E27: ='Dados de demanda e evaporação'!$D$7 -> 0.1612 | F27: =E27*D27 -> 719702.09 | G27: =(C27-F27) -> 25147577 | H27: ='Dados de demanda e evaporação'!$B$7 -> 0.6 | I27: =H27*B27*(3600*24) -> 1607040 | J27: =G27-I27 -> 23540537 | K27: =IF(J27<$D$10,J27,$D$10) -> 23540537
A28: 43132 | B28: 31 | C28: =K27 -> 23540537 | D28: =22.256*C28^0.7153 -> 4173566.7 | E28: ='Dados de demanda e evaporação'!$D$8 -> 0.1428 | F28: =E28*D28 -> 595985.33 | G28: =(C28-F28) -> 22944552 | H28: ='Dados de demanda e evaporação'!$B$7 -> 0.6 | I28: =H28*B28*(3600*24) -> 1607040 | J28: =G28-I28 -> 21337512 | K28: =IF(J28<$D$10,J28,$D$10) -> 21337512
A29: 43160 | B29: 28 | C29: =K28 -> 21337512 | D29: =22.256*C29^0.7153 -> 3890305.1 | E29: ='Dados de demanda e evaporação'!$D$9 -> 0.1395 | F29: =E29*D29 -> 542697.56 | G29: =(C29-F29) -> 20794814 | H29: ='Dados de demanda e evaporação'!$B$7 -> 0.6 | I29: =H29*B29*(3600*24) -> 1451520 | J29: =G29-I29 -> 19343294 | K29: =IF(J29<$D$10,J29,$D$10) -> 19343294
A30: 43191 | B30: 31 | C30: =K29 -> 19343294 | D30: =22.256*C30^0.7153 -> 3626622.4 | E30: ='Dados de demanda e evaporação'!$D$10 -> 0.114 | F30: =E30*D30 -> 413434.95 | G30: =(C30-F30) -> 18929860 | H30: ='Dados de demanda e evaporação'!$B$7 -> 0.6 | I30: =H30*B30*(3600*24) -> 1607040 | J30: =G30-I30 -> 17322820 | K30: =IF(J30<$D$10,J30,$D$10) -> 17322820
A31: 43221 | B31: 30 | C31: =K30 -> 17322820 | D31: =22.256*C31^0.7153 -> 3351436.4 | E31: ='Dados de demanda e evaporação'!$D$11 -> 0.0899 | F31: =E31*D31 -> 301294.13 | G31: =(C31-F31) -> 17021525 | H31: ='Dados de demanda e evaporação'!$B$7 -> 0.6 | I31: =H31*B31*(3600*24) -> 1555200 | J31: =G31-I31 -> 15466325 | K31: =IF(J31<$D$10,J31,$D$10) -> 15466325
A32: 43252 | B32: 31 | C32: =K31 -> 15466325 | D32: =22.256*C32^0.7153 -> 3090407.4 | E32: ='Dados de demanda e evaporação'!$D$12 -> 0.075 | F32: =E32*D32 -> 231780.56 | G32: =(C32-F32) -> 15234545 | H32: ='Dados de demanda e evaporação'!$B$7 -> 0.6 | I32: =H32*B32*(3600*24) -> 1607040 | J32: =G32-I32 -> 13627505 | K32: =IF(J32<$D$10,J32,$D$10) -> 13627505
A33: 43282 | B33: 30 | C33: =K32 -> 13627505 | D33: =22.256*C33^0.7153 -> 2822897.6 | E33: ='Dados de demanda e evaporação'!$D$13 -> 0.0806 | F33: =E33*D33 -> 227525.55 | G33: =(C33-F33) -> 13399979 | H33: ='Dados de demanda e evaporação'!$B$7 -> 0.6 | I33: =H33*B33*(3600*24) -> 1555200 | J33: =G33-I33 -> 11844779 | K33: =IF(J33<$D$10,J33,$D$10) -> 11844779
A34: 43313 | B34: 31 | C34: =K33 -> 11844779 | D34: =22.256*C34^0.7153 -> 2553529.9 | E34: ='Dados de demanda e evaporação'!$D$14 -> 0.0992 | F34: =E34*D34 -> 253310.17 | G34: =(C34-F34) -> 11591469 | H34: ='Dados de demanda e evaporação'!$B$7 -> 0.6 | I34: =H34*B34*(3600*24) -> 1607040 | J34: =G34-I34 -> 9984429.1 | K34: =IF(J34<$D$10,J34,$D$10) -> 9984429.1
A35: 43344 | B35: 31 | C35: =K34 -> 9984429.1 | D35: =22.256*C35^0.7153 -> 2259763.7 | E35: ='Dados de demanda e evaporação'!$D$15 -> 0.126 | F35: =E35*D35 -> 284730.22 | G35: =(C35-F35) -> 9699698.9 | H35: ='Dados de demanda e evaporação'!$B$7 -> 0.6 | I35: =H35*B35*(3600*24) -> 1607040 | J35: =G35-I35 -> 8092658.9 | K35: =IF(J35<$D$10,J35,$D$10) -> 8092658.9
A36: 43374 | B36: 30 | C36: =K35 -> 8092658.9 | D36: =22.256*C36^0.7153 -> 1944485.8 | E36: ='Dados de demanda e evaporação'!$D$16 -> 0.1519 | F36: =E36*D36 -> 295367.39 | G36: =(C36-F36) -> 7797291.5 | H36: ='Dados de demanda e evaporação'!$B$7 -> 0.6 | I36: =H36*B36*(3600*24) -> 1555200 | J36: =G36-I36 -> 6242091.5 | K36: =IF(J36<$D$10,J36,$D$10) -> 6242091.5
A37: 43405 | B37: 31 | C37: =K36 -> 6242091.5 | D37: =22.256*C37^0.7153 -> 1614904.2 | E37: ='Dados de demanda e evaporação'!$D$17 -> 0.156 | F37: =E37*D37 -> 251925.05 | G37: =(C37-F37) -> 5990166.4 | H37: ='Dados de demanda e evaporação'!$B$7 -> 0.6 | I37: =H37*B37*(3600*24) -> 1607040 | J37: =G37-I37 -> 4383126.4 | K37: =IF(J37<$D$10,J37,$D$10) -> 4383126.4
A38: 43435 | B38: 30 | C38: =K37 -> 4383126.4 | D38: =22.256*C38^0.7153 -> 1254051 | E38: ='Dados de demanda e evaporação'!$D$18 -> 0.1612 | F38: =E38*D38 -> 202153.03 | G38: =(C38-F38) -> 4180973.4 | H38: ='Dados de demanda e evaporação'!$B$7 -> 0.6 | I38: =H38*B38*(3600*24) -> 1555200 | J38: =G38-I38 -> 2625773.4 | K38: =IF(J38<$D$10,J38,$D$10) -> 2625773.4
A39: 43466 | B39: 31 | C39: =K38 -> 2625773.4 | D39: =22.256*C39^0.7153 -> 869244.24 | E39: ='Dados de demanda e evaporação'!$D$7 -> 0.1612 | F39: =E39*D39 -> 140122.17 | G39: =(C39-F39) -> 2485651.2 | H39: ='Dados de demanda e evaporação'!$B$7 -> 0.6 | I39: =H39*B39*(3600*24) -> 1607040 | J39: =G39-I39 -> 878611.24 | K39: =IF(J39<$D$10,J39,$D$10) -> 878611.24
A40: 43497 | B40: 31 | C40: =K39 -> 878611.24 | D40: =22.256*C40^0.7153 -> 397232.65 | E40: ='Dados de demanda e evaporação'!$D$8 -> 0.1428 | F40: =E40*D40 -> 56724.822 | G40: =(C40-F40) -> 821886.42 | H40: ='Dados de demanda e evaporação'!$B$7 -> 0.6 | I40: =H40*B40*(3600*24) -> 1607040 | J40: =G40-I40 -> -785153.58 | K40: =IF(J40<$D$10,J40,$D$10) -> -785153.58
A41: 43525 | B41: 28 | C41: =K40 -> -785153.58 | D41: =22.256*C41^0.7153 -> #NUM! | E41: ='Dados de demanda e evaporação'!$D$9 -> 0.1395 | F41: =E41*D41 -> #NUM! | G41: =(C41-F41) -> #NUM! | H41: ='Dados de demanda e evaporação'!$B$7 -> 0.6 | I41: =H41*B41*(3600*24) -> 1451520 | J41: =G41-I41 -> #NUM! | K41: =IF(J41<$D$10,J41,$D$10) -> #NUM!
A42: 43556 | B42: 31 | C42: =K41 -> #NUM! | D42: =22.256*C42^0.7153 -> #NUM! | E42: ='Dados de demanda e evaporação'!$D$10 -> 0.114 | F42: =E42*D42 -> #NUM! | G42: =(C42-F42) -> #NUM! | H42: ='Dados de demanda e evaporação'!$B$7 -> 0.6 | I42: =H42*B42*(3600*24) -> 1607040 | J42: =G42-I42 -> #NUM! | K42: =IF(J42<$D$10,J42,$D$10) -> #NUM!
A43: 43586 | B43: 30 | C43: =K42 -> #NUM! | D43: =22.256*C43^0.7153 -> #NUM! | E43: ='Dados de demanda e evaporação'!$D$11 -> 0.0899 | F43: =E43*D43 -> #NUM! | G43: =(C43-F43) -> #NUM! | H43: ='Dados de demanda e evaporação'!$B$7 -> 0.6 | I43: =H43*B43*(3600*24) -> 1555200 | J43: =G43-I43 -> #NUM! | K43: =IF(J43<$D$10,J43,$D$10) -> #NUM!
A44: 43617 | B44: 31 | C44: =K43 -> #NUM! | D44: =22.256*C44^0.7153 -> #NUM! | E44: ='Dados de demanda e evaporação'!$D$12 -> 0.075 | F44: =E44*D44 -> #NUM! | G44: =(C44-F44) -> #NUM! | H44: ='Dados de demanda e evaporação'!$B$7 -> 0.6 | I44: =H44*B44*(3600*24) -> 1607040 | J44: =G44-I44 -> #NUM! | K44: =IF(J44<$D$10,J44,$D$10) -> #NUM!
A45: 43647 | B45: 30 | C45: =K44 -> #NUM! | D45: =22.256*C45^0.7153 -> #NUM! | E45: ='Dados de demanda e evaporação'!$D$13 -> 0.0806 | F45: =E45*D45 -> #NUM! | G45: =(C45-F45) -> #NUM! | H45: ='Dados de demanda e evaporação'!$B$7 -> 0.6 | I45: =H45*B45*(3600*24) -> 1555200 | J45: =G45-I45 -> #NUM! | K45: =IF(J45<$D$10,J45,$D$10) -> #NUM!
A46: 43678 | B46: 31 | C46: =K45 -> #NUM! | D46: =22.256*C46^0.7153 -> #NUM! | E46: ='Dados de demanda e evaporação'!$D$14 -> 0.0992 | F46: =E46*D46 -> #NUM! | G46: =(C46-F46) -> #NUM! | H46: ='Dados de demanda e evaporação'!$B$7 -> 0.6 | I46: =H46*B46*(3600*24) -> 1607040 | J46: =G46-I46 -> #NUM! | K46: =IF(J46<$D$10,J46,$D$10) -> #NUM!
A47: 43709 | B47: 31 | C47: =K46 -> #NUM! | D47: =22.256*C47^0.7153 -> #NUM! | E47: ='Dados de demanda e evaporação'!$D$15 -> 0.126 | F47: =E47*D47 -> #NUM! | G47: =(C47-F47) -> #NUM! | H47: ='Dados de demanda e evaporação'!$B$7 -> 0.6 | I47: =H47*B47*(3600*24) -> 1607040 | J47: =G47-I47 -> #NUM! | K47: =IF(J47<$D$10,J47,$D$10) -> #NUM!
...

Sheet Dimensionamento polinomial
A1: com equação polinomial grau 2
A4: Volume inicial (m3) | D4: =49086672.63 -> 49086673 | F4: AESA 31/01/2016
A5: Capacidade total de armazenamento | D5: 411686287 | E5: AESA
A6: volume de porão | D6: =8%*$D$5 -> 32934903
A7: Capacidade útil de armazenamento | D7: =D5-D6 -> 3.7875138e+08
A11: Mês | B11: Número de dias do mês | C11: Volume (em m3) | D11: Área (m2) | E11: Evaporação | F11: Volume referente a 8 (m3) | G11: Afluxo Líquido (m3) | H11: Demandas (m3/s) | I11: Volumes das demandas (m3) | J11: Volumes acumulados | K11: Volume final do mês
A12: 44621 | B12: 31 | C12: =$D$4 -> 49086673 | D12: =-7*10^(-9*(C12))^2+0.3302*(C12)+113508 -> 16321927 | E12: ='Dados de demanda e evaporação'!$D8 -> 0.1428 | F12: =E12*D12 -> 2330771.2 | G12: =(C12-F12) -> 46755901 | H12: ='Dados de demanda e evaporação'!$B$7 -> 0.6 | I12: =H12*B12*(3600*24) -> 1607040 | J12: =G12-I12 -> 45148861 | K12: =IF(J12<$D$5,J12,$D$5) -> 45148861
A13: 44652 | B13: 30 | C13: =K12 -> 45148861 | D13: =-7*10^(-9*(C13))^2+0.3302*(C13)+113508 -> 15021662 | E13: ='Dados de demanda e evaporação'!$D9 -> 0.1395 | F13: =E13*D13 -> 2095521.9 | G13: =(C13-F13) -> 43053340 | H13: ='Dados de demanda e evaporação'!$B$7 -> 0.6 | I13: =H13*B13*(3600*24) -> 1555200 | J13: =G13-I13 -> 41498140 | K13: =IF(J13<$D$5,J13,$D$5) -> 41498140
A14: 44682 | B14: 31 | C14: =K13 -> 41498140 | D14: =-7*10^(-9*(C14))^2+0.3302*(C14)+113508 -> 13816194 | E14: ='Dados de demanda e evaporação'!$D10 -> 0.114 | F14: =E14*D14 -> 1575046.1 | G14: =(C14-F14) -> 39923093 | H14: ='Dados de demanda e evaporação'!$B$7 -> 0.6 | I14: =H14*B14*(3600*24) -> 1607040 | J14: =G14-I14 -> 38316053 | K14: =IF(J14<$D$5,J14,$D$5) -> 38316053 | M14: VOLUME MÍNIMO | O14: =MIN(K12:K30) -> 1399588.5
A15: 44713 | B15: 30 | C15: =K14 -> 38316053 | D15: =-7*10^(-9*(C15))^2+0.3302*(C15)+113508 -> 12765469 | E15: ='Dados de demanda e evaporação'!$D11 -> 0.0899 | F15: =E15*D15 -> 1147615.7 | G15: =(C15-F15) -> 37168438 | H15: ='Dados de demanda e evaporação'!$B$7 -> 0.6 | I15: =H15*B15*(3600*24) -> 1555200 | J15: =G15-I15 -> 35613238 | K15: =IF(J15<$D$5,J15,$D$5) -> 35613238
A16: 44743 | B16: 31 | C16: =K15 -> 35613238 | D16: =-7*10^(-9*(C16))^2+0.3302*(C16)+113508 -> 11872999 | E16: ='Dados de demanda e evaporação'!$D12 -> 0.075 | F16: =E16*D16 -> 890474.93 | G16: =(C16-F16) -> 34722763 | H16: ='Dados de demanda e evaporação'!$B$7 -> 0.6 | I16: =H16*B16*(3600*24) -> 1607040 | J16: =G16-I16 -> 33115723 | K16: =IF(J16<$D$5,J16,$D$5) -> 33115723
A17: 44774 | B17: 31 | C17: =K16 -> 33115723 | D17: =-7*10^(-9*(C17))^2+0.3302*(C17)+113508 -> 11048320 | E17: ='Dados de demanda e evaporação'!$D13 -> 0.0806 | F17: =E17*D17 -> 890494.57 | G17: =(C17-F17) -> 32225228 | H17: ='Dados de demanda e evaporação'!$B$7 -> 0.6 | I17: =H17*B17*(3600*24) -> 1607040 | J17: =G17-I17 -> 30618188 | K17: =IF(J17<$D$5,J17,$D$5) -> 30618188
A18: 44805 | B18: 30 | C18: =K17 -> 30618188 | D18: =-7*10^(-9*(C18))^2+0.3302*(C18)+113508 -> 10223634 | E18: ='Dados de demanda e evaporação'!$D14 -> 0.0992 | F18: =E18*D18 -> 1014184.5 | G18: =(C18-F18) -> 29604004 | H18: ='Dados de demanda e evaporação'!$B$7 -> 0.6 | I18: =H18*B18*(3600*24) -> 1555200 | J18: =G18-I18 -> 28048804 | K18: =IF(J18<$D$5,J18,$D$5) -> 28048804
A19: 44835 | B19: 31 | C19: =K18 -> 28048804 | D19: =-7*10^(-9*(C19))^2+0.3302*(C19)+113508 -> 9375223 | E19: ='Dados de demanda e evaporação'!$D15 -> 0.126 | F19: =E19*D19 -> 1181278.1 | G19: =(C19-F19) -> 26867526 | H19: ='Dados de demanda e evaporação'!$B$7 -> 0.6 | I19: =H19*B19*(3600*24) -> 1607040 | J19: =G19-I19 -> 25260486 | K19: =IF(J19<$D$5,J19,$D$5) -> 25260486
A20: 44866 | B20: 30 | C20: =K19 -> 25260486 | D20: =-7*10^(-9*(C20))^2+0.3302*(C20)+113508 -> 8454520.4 | E20: ='Dados de demanda e evaporação'!$D16 -> 0.1519 | F20: =E20*D20 -> 1284241.6 | G20: =(C20-F20) -> 23976244 | H20: ='Dados de demanda e evaporação'!$B$7 -> 0.6 | I20: =H20*B20*(3600*24) -> 1555200 | J20: =G20-I20 -> 22421044 | K20: =IF(J20<$D$5,J20,$D$5) -> 22421044
A21: 44896 | B21: 31 | C21: =K20 -> 22421044 | D21: =-7*10^(-9*(C21))^2+0.3302*(C21)+113508 -> 7516936.8 | E21: ='Dados de demanda e evaporação'!$D17 -> 0.156 | F21: =E21*D21 -> 1172642.1 | G21: =(C21-F21) -> 21248402 | H21: ='Dados de demanda e evaporação'!$B$7 -> 0.6 | I21: =H21*B21*(3600*24) -> 1607040 | J21: =G21-I21 -> 19641362 | K21: =IF(J21<$D$5,J21,$D$5) -> 19641362
A22: 44927 | B22: 31 | C22: =K21 -> 19641362 | D22: =-7*10^(-9*(C22))^2+0.3302*(C22)+113508 -> 6599085.7 | E22: ='Dados de demanda e evaporação'!$D$7 -> 0.1612 | F22: =E22*D22 -> 1063772.6 | G22: =(C22-F22) -> 18577589 | H22: ='Dados de demanda e evaporação'!$B$7 -> 0.6 | I22: =H22*B22*(3600*24) -> 1607040 | J22: =G22-I22 -> 16970549 | K22: =IF(J22<$D$5,J22,$D$5) -> 16970549
A23: 44958 | B23: 28 | C23: =K22 -> 16970549 | D23: =-7*10^(-9*(C23))^2+0.3302*(C23)+113508 -> 5717183.4 | E23: ='Dados de demanda e evaporação'!$D$8 -> 0.1428 | F23: =E23*D23 -> 816413.79 | G23: =(C23-F23) -> 16154136 | H23: ='Dados de demanda e evaporação'!$B$7 -> 0.6 | I23: =H23*B23*(3600*24) -> 1451520 | J23: =G23-I23 -> 14702616 | K23: =IF(J23<$D$5,J23,$D$5) -> 14702616
A24: 44986 | B24: 31 | C24: =K23 -> 14702616 | D24: =-7*10^(-9*(C24))^2+0.3302*(C24)+113508 -> 4968311.7 | E24: ='Dados de demanda e evaporação'!$D$9 -> 0.1395 | F24: =E24*D24 -> 693079.48 | G24: =(C24-F24) -> 14009536 | H24: ='Dados de demanda e evaporação'!$B$7 -> 0.6 | I24: =H24*B24*(3600*24) -> 1607040 | J24: =G24-I24 -> 12402496 | K24: =IF(J24<$D$5,J24,$D$5) -> 12402496
A25: 45017 | B25: 30 | C25: =K24 -> 12402496 | D25: =-7*10^(-9*(C25))^2+0.3302*(C25)+113508 -> 4208812.2 | E25: ='Dados de demanda e evaporação'!$D$10 -> 0.114 | F25: =E25*D25 -> 479804.59 | G25: =(C25-F25) -> 11922691 | H25: ='Dados de demanda e evaporação'!$B$7 -> 0.6 | I25: =H25*B25*(3600*24) -> 1555200 | J25: =G25-I25 -> 10367491 | K25: =IF(J25<$D$5,J25,$D$5) -> 10367491
A26: 45047 | B26: 31 | C26: =K25 -> 10367491 | D26: =-7*10^(-9*(C26))^2+0.3302*(C26)+113508 -> 3536853.7 | E26: ='Dados de demanda e evaporação'!$D$11 -> 0.0899 | F26: =E26*D26 -> 317963.15 | G26: =(C26-F26) -> 10049528 | H26: ='Dados de demanda e evaporação'!$B$7 -> 0.6 | I26: =H26*B26*(3600*24) -> 1607040 | J26: =G26-I26 -> 8442488.3 | K26: =IF(J26<$D$5,J26,$D$5) -> 8442488.3
A27: 45078 | B27: 30 | C27: =K26 -> 8442488.3 | D27: =-7*10^(-9*(C27))^2+0.3302*(C27)+113508 -> 2901217.7 | E27: ='Dados de demanda e evaporação'!$D$12 -> 0.075 | F27: =E27*D27 -> 217591.32 | G27: =(C27-F27) -> 8224897 | H27: ='Dados de demanda e evaporação'!$B$7 -> 0.6 | I27: =H27*B27*(3600*24) -> 1555200 | J27: =G27-I27 -> 6669697 | K27: =IF(J27<$D$5,J27,$D$5) -> 6669697
A28: 45108 | B28: 31 | C28: =K27 -> 6669697 | D28: =-7*10^(-9*(C28))^2+0.3302*(C28)+113508 -> 2315842 | E28: ='Dados de demanda e evaporação'!$D$13 -> 0.0806 | F28: =E28*D28 -> 186656.86 | G28: =(C28-F28) -> 6483040.2 | H28: ='Dados de demanda e evaporação'!$B$7 -> 0.6 | I28: =H28*B28*(3600*24) -> 1607040 | J28: =G28-I28 -> 4876000.2 | K28: =IF(J28<$D$5,J28,$D$5) -> 4876000.2
A29: 45139 | B29: 31 | C29: =K28 -> 4876000.2 | D29: =-7*10^(-9*(C29))^2+0.3302*(C29)+113508 -> 1723563.3 | E29: ='Dados de demanda e evaporação'!$D$14 -> 0.0992 | F29: =E29*D29 -> 170977.47 | G29: =(C29-F29) -> 4705022.7 | H29: ='Dados de demanda e evaporação'!$B$7 -> 0.6 | I29: =H29*B29*(3600*24) -> 1607040 | J29: =G29-I29 -> 3097982.7 | K29: =IF(J29<$D$5,J29,$D$5) -> 3097982.7
A30: 45170 | B30: 30 | C30: =K29 -> 3097982.7 | D30: =-7*10^(-9*(C30))^2+0.3302*(C30)+113508 -> 1136461.9 | E30: ='Dados de demanda e evaporação'!$D$15 -> 0.126 | F30: =E30*D30 -> 143194.2 | G30: =(C30-F30) -> 2954788.5 | H30: ='Dados de demanda e evaporação'!$B$7 -> 0.6 | I30: =H30*B30*(3600*24) -> 1555200 | J30: =G30-I30 -> 1399588.5 | K30: =IF(J30<$D$5,J30,$D$5) -> 1399588.5
A31: 45200 | B31: 31 | C31: =K30 -> 1399588.5 | D31: =-7*10^(-9*(C31))^2+0.3302*(C31)+113508 -> 575652.12 | E31: ='Dados de demanda e evaporação'!$D$16 -> 0.1519 | F31: =E31*D31 -> 87441.557 | G31: =(C31-F31) -> 1312146.9 | H31: ='Dados de demanda e evaporação'!$B$7 -> 0.6 | I31: =H31*B31*(3600*24) -> 1607040 | J31: =G31-I31 -> -294893.07 | K31: =IF(J31<$D$5,J31,$D$5) -> -294893.07
A32: 45231 | B32: 30 | C32: =K31 -> -294893.07 | D32: =-7*10^(-9*(C32))^2+0.3302*(C32)+113508 -> #NUM! | E32: ='Dados de demanda e evaporação'!$D$17 -> 0.156 | F32: =E32*D32 -> #NUM! | G32: =(C32-F32) -> #NUM! | H32: ='Dados de demanda e evaporação'!$B$7 -> 0.6 | I32: =H32*B32*(3600*24) -> 1555200 | J32: =G32-I32 -> #NUM! | K32: =IF(J32<$D$5,J32,$D$5) -> #NUM!
A33: 45261 | B33: 31 | C33: =K32 -> #NUM! | D33: =-7*10^(-9*(C33))^2+0.3302*(C33)+113508 -> #NUM! | E33: ='Dados de demanda e evaporação'!$D$18 -> 0.1612 | F33: =E33*D33 -> #NUM! | G33: =(C33-F33) -> #NUM! | H33: ='Dados de demanda e evaporação'!$B$7 -> 0.6 | I33: =H33*B33*(3600*24) -> 1607040 | J33: =G33-I33 -> #NUM! | K33: =IF(J33<$D$5,J33,$D$5) -> #NUM!
A34: 45292 | B34: 31 | C34: =K33 -> #NUM! | D34: =-7*10^(-9*(C34))^2+0.3302*(C34)+113508 -> #NUM! | E34: ='Dados de demanda e evaporação'!$D$7 -> 0.1612 | F34: =E34*D34 -> #NUM! | G34: =(C34-F34) -> #NUM! | H34: ='Dados de demanda e evaporação'!$B$7 -> 0.6 | I34: =H34*B34*(3600*24) -> 1607040 | J34: =G34-I34 -> #NUM! | K34: =IF(J34<$D$5,J34,$D$5) -> #NUM!
A35: 45323 | B35: 28 | C35: =K34 -> #NUM! | D35: =-7*10^(-9*(C35))^2+0.3302*(C35)+113508 -> #NUM! | E35: ='Dados de demanda e evaporação'!$D$8 -> 0.1428 | F35: =E35*D35 -> #NUM! | G35: =(C35-F35) -> #NUM! | H35: ='Dados de demanda e evaporação'!$B$7 -> 0.6 | I35: =H35*B35*(3600*24) -> 1451520 | J35: =G35-I35 -> #NUM! | K35: =IF(J35<$D$5,J35,$D$5) -> #NUM!
A36: 45352 | B36: 31 | C36: =K35 -> #NUM! | D36: =-7*10^(-9*(C36))^2+0.3302*(C36)+113508 -> #NUM! | E36: ='Dados de demanda e evaporação'!$D$9 -> 0.1395 | F36: =E36*D36 -> #NUM! | G36: =(C36-F36) -> #NUM! | H36: ='Dados de demanda e evaporação'!$B$7 -> 0.6 | I36: =H36*B36*(3600*24) -> 1607040 | J36: =G36-I36 -> #NUM! | K36: =IF(J36<$D$5,J36,$D$5) -> #NUM!
A37: 45383 | B37: 30 | C37: =K36 -> #NUM! | D37: =-7*10^(-9*(C37))^2+0.3302*(C37)+113508 -> #NUM! | E37: ='Dados de demanda e evaporação'!$D$10 -> 0.114 | F37: =E37*D37 -> #NUM! | G37: =(C37-F37) -> #NUM! | H37: ='Dados de demanda e evaporação'!$B$7 -> 0.6 | I37: =H37*B37*(3600*24) -> 1555200 | J37: =G37-I37 -> #NUM! | K37: =IF(J37<$D$5,J37,$D$5) -> #NUM!
A38: 45413 | B38: 31 | C38: =K37 -> #NUM! | D38: =-7*10^(-9*(C38))^2+0.3302*(C38)+113508 -> #NUM! | E38: ='Dados de demanda e evaporação'!$D$11 -> 0.0899 | F38: =E38*D38 -> #NUM! | G38: =(C38-F38) -> #NUM! | H38: ='Dados de demanda e evaporação'!$B$7 -> 0.6 | I38: =H38*B38*(3600*24) -> 1607040 | J38: =G38-I38 -> #NUM! | K38: =IF(J38<$D$5,J38,$D$5) -> #NUM!
A39: 45444 | B39: 30 | C39: =K38 -> #NUM! | D39: =-7*10^(-9*(C39))^2+0.3302*(C39)+113508 -> #NUM! | E39: ='Dados de demanda e evaporação'!$D$12 -> 0.075 | F39: =E39*D39 -> #NUM! | G39: =(C39-F39) -> #NUM! | H39: ='Dados de demanda e evaporação'!$B$7 -> 0.6 | I39: =H39*B39*(3600*24) -> 1555200 | J39: =G39-I39 -> #NUM! | K39: =IF(J39<$D$5,J39,$D$5) -> #NUM!
A40: 45474 | B40: 31 | C40: =K39 -> #NUM! | D40: =-7*10^(-9*(C40))^2+0.3302*(C40)+113508 -> #NUM! | E40: ='Dados de demanda e evaporação'!$D$13 -> 0.0806 | F40: =E40*D40 -> #NUM! | G40: =(C40-F40) -> #NUM! | H40: ='Dados de demanda e evaporação'!$B$7 -> 0.6 | I40: =H40*B40*(3600*24) -> 1607040 | J40: =G40-I40 -> #NUM! | K40: =IF(J40<$D$5,J40,$D$5) -> #NUM!
A41: 45505 | B41: 31 | C41: =K40 -> #NUM! | D41: =-7*10^(-9*(C41))^2+0.3302*(C41)+113508 -> #NUM! | E41: ='Dados de demanda e evaporação'!$D$14 -> 0.0992 | F41: =E41*D41 -> #NUM! | G41: =(C41-F41) -> #NUM! | H41: ='Dados de demanda e evaporação'!$B$7 -> 0.6 | I41: =H41*B41*(3600*24) -> 1607040 | J41: =G41-I41 -> #NUM! | K41: =IF(J41<$D$5,J41,$D$5) -> #NUM!
A42: 45536 | B42: 30 | C42: =K41 -> #NUM! | D42: =-7*10^(-9*(C42))^2+0.3302*(C42)+113508 -> #NUM! | E42: ='Dados de demanda e evaporação'!$D$15 -> 0.126 | F42: =E42*D42 -> #NUM! | G42: =(C42-F42) -> #NUM! | H42: ='Dados de demanda e evaporação'!$B$7 -> 0.6 | I42: =H42*B42*(3600*24) -> 1555200 | J42: =G42-I42 -> #NUM! | K42: =IF(J42<$D$5,J42,$D$5) -> #NUM!
A43: 45566 | B43: 31 | C43: =K42 -> #NUM! | D43: =-7*10^(-9*(C43))^2+0.3302*(C43)+113508 -> #NUM! | E43: ='Dados de demanda e evaporação'!$D$16 -> 0.1519 | F43: =E43*D43 -> #NUM! | G43: =(C43-F43) -> #NUM! | H43: ='Dados de demanda e evaporação'!$B$7 -> 0.6 | I43: =H43*B43*(3600*24) -> 1607040 | J43: =G43-I43 -> #NUM! | K43: =IF(J43<$D$5,J43,$D$5) -> #NUM!
A44: 45597 | B44: 30 | C44: =K43 -> #NUM! | D44: =-7*10^(-9*(C44))^2+0.3302*(C44)+113508 -> #NUM! | E44: ='Dados de demanda e evaporação'!$D$17 -> 0.156 | F44: =E44*D44 -> #NUM! | G44: =(C44-F44) -> #NUM! | H44: ='Dados de demanda e evaporação'!$B$7 -> 0.6 | I44: =H44*B44*(3600*24) -> 1555200 | J44: =G44-I44 -> #NUM! | K44: =IF(J44<$D$5,J44,$D$5) -> #NUM!
A45: 45627 | B45: 31 | C45: =K44 -> #NUM! | D45: =-7*10^(-9*(C45))^2+0.3302*(C45)+113508 -> #NUM! | E45: ='Dados de demanda e evaporação'!$D$18 -> 0.1612 | F45: =E45*D45 -> #NUM! | G45: =(C45-F45) -> #NUM! | H45: ='Dados de demanda e evaporação'!$B$7 -> 0.6 | I45: =H45*B45*(3600*24) -> 1607040 | J45: =G45-I45 -> #NUM! | K45: =IF(J45<$D$5,J45,$D$5) -> #NUM!
...
